<?xml version="1.0"?>
<robot xmlns:xacro="http://www.ros.org/wiki/xacro" >

    <!-- <xacro:include filename="inertial_macros.xacro"/> -->

    <material name="white">
        <color rgba="1 1 1 1" />
    </material>

    <material name="orange">
        <color rgba="1 0.3 0.1 1"/>
    </material>

    <material name="blue">
        <color rgba="0.2 0.2 1 1"/>
    </material>

    <material name="black">
        <color rgba="0 0 0 1"/>
    </material>

     <material name="red">
        <color rgba="1 0 0 1"/>
    </material>

    <!-- BASE LINK -->

    <link name="base_link">

    </link>


    <!-- CHASSIS LINK -->

    <joint name="chassis_joint" type="fixed">
        <parent link="base_link"/>
        <child link="chassis"/>
        <origin xyz="-0.1 0 0"/>
    </joint>

    <link name="chassis">
        <visual>
            <origin xyz="0.2575 0 0.0675"/>
            <geometry>
                <box size="0.515 0.31 0.135"/> 
                <!-- l b h -->
            </geometry>
            <material name="white"/>
        </visual>        
    </link>

  <!-- Rear LEFT WHEEL -->
  
<joint name="rear_left_wheel_joint" type="continuous">
    <parent link="base_link"/>
    <child link="rear_left_wheel"/>
    <origin xyz="0 0.18 0" rpy="-${pi/2} 0 0"/>    
    <!-- y = b + thickness of wheel/2 + 0.5(mm) -->
    <!-- connected with base link -->
    <axis xyz="0 0 1"/>
</joint>

<link name="rear_left_wheel">
    <visual>
        <geometry>
            <cylinder length="0.04" radius="0.0485" />
        </geometry>
        <material name="blue"/>
    </visual>
</link>
    </robot>